Workbook

Sheet Assignment Details
B3: Case Study
B5: Mr. Peter is 30 yrs old.
B6: With Earning of Rs 1 Lac per month.
B7: Monthly expense Rs 40 k
B8: EMI are 30 k pm.
B9: Total Expense - 70 k pm
B11: Mr Peter has son who is 2 yrs old and he wanted to plan for education, marriage and house purchase !!
B12: He has a health insurance of floater policy 3 lac including wife and son.
B13: He has a Term plan for 50 lac.
B15: He wants to plan for :
B16: Child Education- PV - 20 lacs
B17: Marriage Planning -PV-20 lac
... B19: Pl construct a Dummy plan for him to help him achieve his financial goals!!

Sheet Portfolio
B7: Clients Name | D7: Mr. Peter
B8: Clients Age | D8: 30
B9: Date of commencement | D9: =DATE(2025,6,6) -> 45814
B10: Time frame | D10: As per Goal
B11: Goals to achieve | D11: Child Education | E11: Marriage Planning | F11: Buying a House
B13: Financial Assesment Report
B14: Risk Protection Planning
C16: Plans | D16: Present coverage | E16: Recommended | F16: *Note (if any)
C17: Health Insurance cover | D17: 300000 | E17: Top-up
C18: Disability Income rider | D18: NA
C19: Term Plan | D19: 5000000 | E19: 1cr
B24: Education Planning for kid
C25: Targeted Amount | D25: 2000000
C27: Child's Present Age | D27: 2
C28: Funds required at age | D28: 18
C29: ="Total time left to reach Goal @"&D28&" yrs" -> Total time left to reach Goal @18 yrs | D29: =D28-D27 -> 16
C30: Time left for Investment to achieve goal | D30: =D29-2 -> 14
C31: Present Value taken | D31: =D25 -> 2000000
C32: ="Future Value @ "& D28&"th"&" year" -> Future Value @ 18th year | D32: =D31*(1+'Calculation & Assumption'!D9)^D29 -> 5904327.5
C34: Recommended Monthly SIP's in MF Equity fund
C36: Scheme Name | D36: Amount p.m | E36: SIP Date | F36: Date of Commencement
C37: ='Scheme Recommendation'!C7 -> Nippon India Large Cap Fund - Growth | D37: 2000 | E37: =DATE(2025,6,9) -> 45817
C38: ='Scheme Recommendation'!C13 -> HDFC Mid-Cap Opportunities Fund - Growth | D38: 2000 | E38: =DATE(2025,6,9) -> 45817
D39: 2000 | E39: =DATE(2025,6,15) -> 45823
D40: 2000 | E40: =DATE(2025,6,22) -> 45830
C43: Monthly SIP pm >>> | D43: =SUM(D37:D42) -> 8000
C44: Return Expectation CAGR | D44: ='Calculation & Assumption'!D17 -> 0.17
C45: Duration | D45: =D30 -> 14
C46: Maturity value of SIPs | D46: ='Calculation & Assumption'!D21 -> 5512838.7
C48: ="Note: When the child turn "& D29&" years of age, we highly recommend to Redeem the fund with approx. value of Rs "& ROUND(D46,0)&" & then re invest / park it in Liquid Funds or Bank FD's for next 2 years & expect a return of "&D51*100&"%" -> Note: When the child turn 16 years of age, we highly recommend to Redeem the fund with approx. value of Rs 5512839 & then re invest / park it in Liquid Funds or Bank FD's for next 2 years & expect a return of 6%
C51: Liquid Fund/Bank FD Rate | D51: ='Calculation & Assumption'!$D$29 -> 0.06
C52: Re-invested Amount | D52: =D46 -> 5512838.7
C53: Duration | D53: 2
C55: Total Maturity Amount | D55: =D52*(1+D51)^D53 -> 6194225.6
B58: Marriage Planning for kid
C59: Targeted Amount | D59: 2000000
C61: Child's Present Age | D61: 2
C62: Funds required at age | D62: 25
C63: ="Total time left to reach Goal @"&D62&" yrs" -> Total time left to reach Goal @25 yrs | D63: =D62-D61 -> 23
C64: Time left for Investment to achieve goal | D64: =D63-2 -> 21
...

Sheet Calculation & Assumption
C2: SIP return Calculator
C5: Education | H5: Marriage | N5: House
C7: Requirement | H7: Requirement | N7: Requirement
C8: Present Value of Targeted Amount | D8: =Portfolio!D31 -> 2000000 | H8: Present Value | I8: =Portfolio!D59 -> 2000000 | N8: Present Value | O8: =Portfolio!D96 -> 7000000
C9: Inflation | D9: =D30 -> 0.07 | H9: Inflation | I9: =D32 -> 0.07 | N9: Inflation | O9: =D34 -> 0.08
C10: Duration | D10: =Portfolio!D29 -> 16 | H10: Duration | I10: =Portfolio!D62 -> 25 | N10: Duration | O10: =Portfolio!D95 -> 10
C12: Future Values of Corpus Required | D12: =D8*(1+D9)^D10 -> 5904327.5 | H12: Future Values of Corpus Required | I12: =I8*(1+I9)^I10 -> 10854865 | N12: Future Values of Corpus Required | O12: =O8*(1+O9)^O10 -> 15112475
C14: Investment Plan | H14: Investment Plan | N14: Investment Plan
C15: SIP amount | D15: =Portfolio!D43 -> 8000 | H15: SIP amount | I15: =Portfolio!D77 -> 3500
C16: Duration | D16: =Portfolio!D30 -> 14 | H16: Duration | I16: =Portfolio!D63 -> 23 | N16: In Salary Projection Sheet
C17: Annual return | D17: =D31 -> 0.17 | H17: Annual return | I17: =D33 -> 0.16
C18: Total Months | D18: =D16*12 -> 168 | H18: Total Months | I18: =I16*12 -> 276
C19: Monthly return | D19: =D17/12 -> 0.014166667 | H19: Monthly return | I19: =I17/12 -> 0.013333333
C21: Future Value of Investment | D21: =D15*((1+D19)^D18-1)*(1+D19)/D19 -> 5512838.7 | H21: Future Value of Investment | I21: =I15*((1+I19)^I18-1)*(1+I19)/I19 -> 10026584
C23: Total Invested | D23: =D15*D18 -> 1344000 | H23: Total Invested | I23: =I15*I18 -> 966000
C24: Wealth Gained | D24: =D21-D23 -> 4168838.7 | H24: Wealth Gained | I24: =I21-I23 -> 9060583.8
C28: Assumptions
C29: Liquid Fund/Bank FD Rate | D29: 0.06
C30: Inflation for Education | D30: 0.07
C31: CAGR for Education | D31: 0.17
C32: Inflation for Marriage | D32: 0.07
C33: CAGR for Marriage | D33: 0.16
C34: Inflation for House | D34: 0.08
C35: CAGR for House | D35: 0.17
C36: SIP step-up for House | D36: 0.1

Sheet Projection
P2: House | U2: Education | Y2: Marriage
P3: Percent of Disposable income before investment | R3: 0.7 | U3: CAGR | V3: ='Calculation & Assumption'!D31 -> 0.17 | Y3: CAGR | Z3: ='Calculation & Assumption'!D33 -> 0.16
P4: CAGR | R4: ='Calculation & Assumption'!D35 -> 0.17
G5: Year | H5: salary | I5: Expected salary hike | J5: Expenses | K5: Expected inc. in expense | L5: EMI | M5: Disposable Income before Investment | N5: % inc in Disposable income | P5: SIP amount | Q5: Step-up % | R5: Annual Amount | S5: FV | U5: SIP amount | V5: Annual Amount | W5: FV | Y5: SIP amount | Z5: Annual Amount | AA5: FV | AC5: Income Left After Investment (pm)
B6: EMI | C6: House | D6: Education | E6: Marriage | F6: 0 | G6: 2025 | H6: 100000 | J6: 40000 | L6: 30000 | M6: =H6-SUM(J6,L6) -> 30000 | P6: =Portfolio!D108 -> 15500.001 | R6: =P6*12 -> 186000.01 | S6: =R6*(1+$R$4)^($F$16-F6) -> 894070.14 | U6: =Portfolio!D43 -> 8000 | V6: =U6*12 -> 96000 | W6: =V6*(1+$V$3)^($F$20-F6) -> 864715.61 | Y6: =Portfolio!D77 -> 3500 | Z6: =Y6*12 -> 42000 | AA6: =Z6*(1+$Z$3)^($F$29-F6) -> 1275801.3 | AC6: =H6-SUM(J6,L6,P6,U6,Y6) -> 2999.999
F7: =F6+1 -> 1 | G7: =G6+1 -> 2026 | H7: =H6*(1+I7) -> 108000 | I7: 0.08 | J7: =J6*(1+K7) -> 41200 | K7: 0.03 | L7: 30000 | M7: =H7-SUM(J7,L7) -> 36800 | N7: =M7/M6-1 -> 0.22666667 | P7: =P6*(1+Q7) -> 19375.001 | Q7: 0.25 | R7: =P7*12 -> 232500.02 | S7: =R7*(1+$R$4)^($F$16-F7) -> 955203.14 | U7: =U6 -> 8000 | V7: =U7*12 -> 96000 | W7: =V7*(1+$V$3)^($F$20-F7) -> 739073.17 | Y7: =Y6 -> 3500 | Z7: =Y7*12 -> 42000 | AA7: =Z7*(1+$Z$3)^($F$29-F7) -> 1099828.7 | AC7: =H7-SUM(J7,L7,P7,U7,Y7) -> 5924.9987
F8: =F7+1 -> 2 | G8: =G7+1 -> 2027 | H8: =H7*(1+I8) -> 116720.71 | I8: 0.08074728 | J8: =J7*(1+K8) -> 42472.218 | K8: 0.030879067 | L8: 30000 | M8: =H8-SUM(J8,L8) -> 44248.489 | N8: =M8/M7-1 -> 0.20240458 | P8: =P7*(1+Q8) -> 24317.877 | Q8: 0.25511613 | R8: =P8*12 -> 291814.52 | S8: =R8*(1+$R$4)^($F$16-F8) -> 1024693.1 | U8: =U7 -> 8000 | V8: =U8*12 -> 96000 | W8: =V8*(1+$V$3)^($F$20-F8) -> 631686.47 | Y8: =Y7 -> 3500 | Z8: =Y8*12 -> 42000 | AA8: =Z8*(1+$Z$3)^($F$29-F8) -> 948128.2 | AC8: =H8-SUM(J8,L8,P8,U8,Y8) -> 8430.6121
F9: =F8+1 -> 3 | G9: =G8+1 -> 2028 | H9: =H8*(1+I9) -> 126233.62 | I9: 0.081501541 | J9: =J8*(1+K9) -> 43822.15 | K9: 0.031783893 | L9: 30000 | M9: =H9-SUM(J9,L9) -> 52411.474 | N9: =M9/M8-1 -> 0.18448054 | P9: =P8*(1+Q9) -> 30648.719 | Q9: 0.26033697 | R9: =P9*12 -> 367784.63 | S9: =R9*(1+$R$4)^($F$16-F9) -> 1103810.7 | U9: =U8 -> 8000 | V9: =U9*12 -> 96000 | W9: =V9*(1+$V$3)^($F$20-F9) -> 539902.96 | Y9: =Y8 -> 3500 | Z9: =Y9*12 -> 42000 | AA9: =Z9*(1+$Z$3)^($F$29-F9) -> 817351.9 | AC9: =H9-SUM(J9,L9,P9,U9,Y9) -> 10262.755
F10: =F9+1 -> 4 | G10: =G9+1 -> 2029 | H10: =H9*(1+I10) -> 136617.96 | I10: 0.082262848 | J10: =J9*(1+K10) -> 45255.802 | K10: 0.032715232 | L10: 30000 | M10: =H10-SUM(J10,L10) -> 61362.159 | N10: =M10/M9-1 -> 0.17077722 | P10: =P9*(1+Q10) -> 38791 | Q10: 0.26566464 | R10: =P10*12 -> 465492 | S10: =R10*(1+$R$4)^($F$16-F10) -> 1194063.4 | U10: =U9 -> 8000 | V10: =U10*12 -> 96000 | W10: =V10*(1+$V$3)^($F$20-F10) -> 461455.53 | Y10: =Y9 -> 3500 | Z10: =Y10*12 -> 42000 | AA10: =Z10*(1+$Z$3)^($F$29-F10) -> 704613.7 | AC10: =H10-SUM(J10,L10,P10,U10,Y10) -> 11071.159
F11: =F10+1 -> 5 | G11: =G10+1 -> 2030 | H11: =H10*(1+I11) -> 147961.52 | I11: 0.083031265 | J11: =J10*(1+K11) -> 46779.739 | K11: 0.033673861 | M11: =H11-SUM(J11,L11) -> 101181.78 | N11: =M11/M10-1 -> 0.64892802 | P11: =P10*(1+Q11) -> 49307.292 | Q11: 0.27110135 | R11: =P11*12 -> 591687.51 | S11: =R11*(1+$R$4)^($F$16-F11) -> 1297244.1 | U11: =U10 -> 8000 | V11: =U11*12 -> 96000 | W11: =V11*(1+$V$3)^($F$20-F11) -> 394406.43 | Y11: =Y10 -> 3500 | Z11: =Y11*12 -> 42000 | AA11: =Z11*(1+$Z$3)^($F$29-F11) -> 607425.61 | AC11: =H11-SUM(J11,L11,P11,U11,Y11) -> 40374.492
F12: =F11+1 -> 6 | G12: =G11+1 -> 2031 | H12: =H11*(1+I12) -> 160361.71 | I12: 0.083806861 | J12: =J11*(1+K12) -> 48401.152 | K12: 0.034660581 | M12: =H12-SUM(J12,L12) -> 111960.56 | N12: =M12/M11-1 -> 0.10652884 | P12: =P11*(1+Q12) -> 62948.12 | Q12: 0.27664931 | R12: =P12*12 -> 755377.45 | S12: =R12*(1+$R$4)^($F$16-F12) -> 1415492.1 | U12: =U11 -> 8000 | V12: =U12*12 -> 96000 | W12: =V12*(1+$V$3)^($F$20-F12) -> 337099.51 | Y12: =Y11 -> 3500 | Z12: =Y12*12 -> 42000 | AA12: =Z12*(1+$Z$3)^($F$29-F12) -> 523642.76 | AC12: =H12-SUM(J12,L12,P12,U12,Y12) -> 37512.441
F13: =F12+1 -> 7 | G13: =G12+1 -> 2032 | H13: =H12*(1+I13) -> 173926.66 | I13: 0.084589701 | J13: =J12*(1+K13) -> 50127.922 | K13: 0.035676213 | M13: =H13-SUM(J13,L13) -> 123798.74 | N13: =M13/M12-1 -> 0.10573526 | P13: =P12*(1+Q13) -> 80719.055 | Q13: 0.28231081 | R13: =P13*12 -> 968628.66 | S13: =R13*(1+$R$4)^($F$16-F13) -> 1551368.3 | U13: =U12 -> 8000 | V13: =U13*12 -> 96000 | W13: =V13*(1+$V$3)^($F$20-F13) -> 288119.24 | Y13: =Y12 -> 3500 | Z13: =Y13*12 -> 42000 | AA13: =Z13*(1+$Z$3)^($F$29-F13) -> 451416.18 | AC13: =H13-SUM(J13,L13,P13,U13,Y13) -> 31579.686
F14: =F13+1 -> 8 | G14: =G13+1 -> 2033 | H14: =H13*(1+I14) -> 188776.5 | I14: 0.085379854 | J14: =J13*(1+K14) -> 51968.7 | K14: 0.036721606 | M14: =H14-SUM(J14,L14) -> 136807.8 | N14: =M14/M13-1 -> 0.10508229 | P14: =P13*(1+Q14) -> 103973.26 | Q14: 0.28808817 | R14: =P14*12 -> 1247679.1 | S14: =R14*(1+$R$4)^($F$16-F14) -> 1707947.9 | U14: =U13 -> 8000 | V14: =U14*12 -> 96000 | W14: =V14*(1+$V$3)^($F$20-F14) -> 246255.76 | Y14: =Y13 -> 3500 | Z14: =Y14*12 -> 42000 | AA14: =Z14*(1+$Z$3)^($F$29-F14) -> 389151.88 | AC14: =H14-SUM(J14,L14,P14,U14,Y14) -> 21334.537
F15: =F14+1 -> 9 | G15: =G14+1 -> 2034 | H15: =H14*(1+I15) -> 205044.76 | I15: 0.086177388 | J15: =J14*(1+K15) -> 53932.994 | K15: 0.037797631 | M15: =H15-SUM(J15,L15) -> 151111.77 | N15: =M15/M14-1 -> 0.10455524 | P15: =P14*(1+Q15) -> 134539.71 | Q15: 0.29398376 | R15: =P15*12 -> 1614476.5 | S15: =R15*(1+$R$4)^($F$16-F15) -> 1888937.5 | U15: =U14 -> 8000 | V15: =U15*12 -> 96000 | W15: =V15*(1+$V$3)^($F$20-F15) -> 210475.01 | Y15: =Y14 -> 3500 | Z15: =Y15*12 -> 42000 | AA15: =Z15*(1+$Z$3)^($F$29-F15) -> 335475.76 | AC15: =H15-SUM(J15,L15,P15,U15,Y15) -> 5072.0584
F16: =F15+1 -> 10 | G16: =G15+1 -> 2035 | H16: =H15*(1+I16) -> 222880.04 | I16: 0.086982371 | J16: =J15*(1+K16) -> 56031.267 | K16: 0.038905187 | M16: =H16-SUM(J16,L16) -> 166848.77 | N16: =M16/M15-1 -> 0.1041415 | P16: =P15*(1+Q16) -> 174901.62 | Q16: 0.3 | R16: =P16*12 -> 2098819.5 | S16: =R16*(1+$R$4)^($F$16-F16) -> 2098819.5 | U16: =U15 -> 8000 | V16: =U16*12 -> 96000 | W16: =V16*(1+$V$3)^($F$20-F16) -> 179893.17 | Y16: =Y15 -> 3500 | Z16: =Y16*12 -> 42000 | AA16: =Z16*(1+$Z$3)^($F$29-F16) -> 289203.24 | AC16: =H16-SUM(J16,L16,P16,U16,Y16) -> -19552.848
F17: =F16+1 -> 11 | G17: =G16+1 -> 2036 | H17: =H16*(1+I17) -> 242447.77 | I17: 0.087794874 | J17: =J16*(1+K17) -> 58275.05 | K17: 0.040045196 | M17: =H17-SUM(J17,L17) -> 184172.72 | N17: =M17/M16-1 -> 0.1038302 | P17: Maturity Amount | S17: =SUM(S6:S16) -> 15131650 | U17: =U16 -> 8000 | V17: =U17*12 -> 96000 | W17: =V17*(1+$V$3)^($F$20-F17) -> 153754.85 | Y17: =Y16 -> 3500 | Z17: =Y17*12 -> 42000 | AA17: =Z17*(1+$Z$3)^($F$29-F17) -> 249313.14 | AC17: =H17-SUM(J17,L17,P17,U17,Y17) -> 172672.72
F18: =F17+1 -> 12 | G18: =G17+1 -> 2037 | H18: =H17*(1+I18) -> 263932.27 | I18: 0.088614966 | J18: =J17*(1+K18) -> 60677.067 | K18: 0.041218609 | M18: =H18-SUM(J18,L18) -> 203255.2 | N18: =M18/M17-1 -> 0.10361189 | U18: =U17 -> 8000 | V18: =U18*12 -> 96000 | W18: =V18*(1+$V$3)^($F$20-F18) -> 131414.4 | Y18: =Y17 -> 3500 | Z18: =Y18*12 -> 42000 | AA18: =Z18*(1+$Z$3)^($F$29-F18) -> 214925.12 | AC18: =H18-SUM(J18,L18,P18,U18,Y18) -> 191755.2
F19: =F18+1 -> 13 | G19: =G18+1 -> 2038 | H19: =H18*(1+I19) -> 287539.09 | I19: 0.089442719 | J19: =J18*(1+K19) -> 63251.376 | K19: 0.042426407 | M19: =H19-SUM(J19,L19) -> 224287.71 | N19: =M19/M18-1 -> 0.10347833 | U19: =U18 -> 8000 | V19: =U19*12 -> 96000 | W19: =V19*(1+$V$3)^($F$20-F19) -> 112320 | Y19: =Y18 -> 3500 | Z19: =Y19*12 -> 42000 | AA19: =Z19*(1+$Z$3)^($F$29-F19) -> 185280.27 | AC19: =H19-SUM(J19,L19,P19,U19,Y19) -> 212787.71
F20: =F19+1 -> 14 | G20: =G19+1 -> 2039 | H20: =H19*(1+I20) -> 313497.6 | I20: 0.090278204 | J20: =J19*(1+K20) -> 66013.538 | K20: 0.043669595 | M20: =H20-SUM(J20,L20) -> 247484.06 | N20: =M20/M19-1 -> 0.1034223 | U20: =U19 -> 8000 | V20: =U20*12 -> 96000 | W20: =V20*(1+$V$3)^($F$20-F20) -> 96000 | Y20: =Y19 -> 3500 | Z20: =Y20*12 -> 42000 | AA20: =Z20*(1+$Z$3)^($F$29-F20) -> 159724.37 | AC20: =H20-SUM(J20,L20,P20,U20,Y20) -> 235984.06
F21: =F20+1 -> 15 | G21: =G20+1 -> 2040 | H21: =H20*(1+I21) -> 342063.97 | I21: 0.091121493 | J21: =J20*(1+K21) -> 68980.795 | K21: 0.044949212 | M21: =H21-SUM(J21,L21) -> 273083.17 | N21: =M21/M20-1 -> 0.10343742 | U21: Maturity Amount | W21: =SUM(W6:W20) -> 5386572.1 | Y21: =Y20 -> 3500 | Z21: =Y21*12 -> 42000 | AA21: =Z21*(1+$Z$3)^($F$29-F21) -> 137693.43 | AC21: =H21-SUM(J21,L21,P21,U21,Y21) -> 269583.17
F22: =F21+1 -> 16 | G22: =G21+1 -> 2041 | H22: =H21*(1+I22) -> 373524.5 | I22: 0.09197266 | J22: =J21*(1+K22) -> 72172.283 | K22: 0.046266325 | M22: =H22-SUM(J22,L22) -> 301352.22 | N22: =M22/M21-1 -> 0.10351808 | Y22: =Y21 -> 3500 | Z22: =Y22*12 -> 42000 | AA22: =Z22*(1+$Z$3)^($F$29-F22) -> 118701.23 | AC22: =H22-SUM(J22,L22,P22,U22,Y22) -> 297852.22
F23: =F22+1 -> 17 | G23: =G22+1 -> 2042 | H23: =H22*(1+I23) -> 408199.44 | I23: 0.092831777 | J23: =J22*(1+K23) -> 75609.274 | K23: 0.047622032 | M23: =H23-SUM(J23,L23) -> 332590.17 | N23: =M23/M22-1 -> 0.10365927 | Y23: =Y22 -> 3500 | Z23: =Y23*12 -> 42000 | AA23: =Z23*(1+$Z$3)^($F$29-F23) -> 102328.65 | AC23: =H23-SUM(J23,L23,P23,U23,Y23) -> 329090.17
F24: =F23+1 -> 18 | G24: =G23+1 -> 2043 | H24: =H23*(1+I24) -> 446447.29 | I24: 0.093698919 | J24: =J23*(1+K24) -> 79315.448 | K24: 0.049017464 | M24: =H24-SUM(J24,L24) -> 367131.84 | N24: =M24/M23-1 -> 0.10385656 | Y24: =Y23 -> 3500 | Z24: =Y24*12 -> 42000 | AA24: =Z24*(1+$Z$3)^($F$29-F24) -> 88214.35 | AC24: =H24-SUM(J24,L24,P24,U24,Y24) -> 363631.84
F25: =F24+1 -> 19 | G25: =G24+1 -> 2044 | H25: =H24*(1+I25) -> 488669.67 | I25: 0.094574161 | J25: =J24*(1+K25) -> 83317.213 | K25: 0.050453785 | M25: =H25-SUM(J25,L25) -> 405352.46 | N25: =M25/M24-1 -> 0.10410596 | Y25: =Y24 -> 3500 | Z25: =Y25*12 -> 42000 | AA25: =Z25*(1+$Z$3)^($F$29-F25) -> 76046.853 | AC25: =H25-SUM(J25,L25,P25,U25,Y25) -> 401852.46
F26: =F25+1 -> 20 | G26: =G25+1 -> 2045 | H26: =H25*(1+I26) -> 535316.89 | I26: 0.095457579 | J26: =J25*(1+K26) -> 87644.059 | K26: 0.051932194 | M26: =H26-SUM(J26,L26) -> 447672.83 | N26: =M26/M25-1 -> 0.1044039 | Y26: =Y25 -> 3500 | Z26: =Y26*12 -> 42000 | AA26: =Z26*(1+$Z$3)^($F$29-F26) -> 65557.632 | AC26: =H26-SUM(J26,L26,P26,U26,Y26) -> 444172.83
F27: =F26+1 -> 21 | G27: =G26+1 -> 2046 | H27: =H26*(1+I27) -> 586894.27 | I27: 0.096349248 | J27: =J26*(1+K27) -> 92328.977 | K27: 0.053453923 | M27: =H27-SUM(J27,L27) -> 494565.3 | N27: =M27/M26-1 -> 0.10474717 | Y27: =Y26 -> 3500 | Z27: =Y27*12 -> 42000 | AA27: =Z27*(1+$Z$3)^($F$29-F27) -> 56515.2 | AC27: =H27-SUM(J27,L27,P27,U27,Y27) -> 491065.3
F28: =F27+1 -> 22 | G28: =G27+1 -> 2047 | H28: =H27*(1+I28) -> 643969.3 | I28: 0.097249247 | J28: =J27*(1+K28) -> 97408.94 | K28: 0.055020243 | M28: =H28-SUM(J28,L28) -> 546560.36 | N28: =M28/M27-1 -> 0.10513286 | Y28: =Y27 -> 3500 | Z28: =Y28*12 -> 42000 | AA28: =Z28*(1+$Z$3)^($F$29-F28) -> 48720 | AC28: =H28-SUM(J28,L28,P28,U28,Y28) -> 543060.36
F29: =F28+1 -> 23 | G29: =G28+1 -> 2048 | H29: =H28*(1+I29) -> 707179.81 | I29: 0.098157653 | J29: =J28*(1+K29) -> 102925.45 | K29: 0.056632459 | M29: =H29-SUM(J29,L29) -> 604254.37 | N29: =M29/M28-1 -> 0.10555835 | Y29: =Y28 -> 3500 | Z29: =Y29*12 -> 42000 | AA29: =Z29*(1+$Z$3)^($F$29-F29) -> 42000 | AC29: =H29-SUM(J29,L29,P29,U29,Y29) -> 600754.37
F30: =F29+1 -> 24 | G30: =G29+1 -> 2049 | H30: =H29*(1+I30) -> 777243.33 | I30: 0.099074544 | J30: =J29*(1+K30) -> 108925.17 | K30: 0.058291916 | M30: =H30-SUM(J30,L30) -> 668318.16 | N30: =M30/M29-1 -> 0.10602124 | Y30: Maturity Amount | AA30: =SUM(AA6:AA29) -> 8987059.5
F31: =F30+1 -> 25 | G31: =G30+1 -> 2050 | H31: =H30*(1+I31) -> 854967.66 | I31: 0.1 | J31: =J30*(1+K31) -> 115460.68 | K31: 0.06 | M31: =H31-SUM(J31,L31) -> 739506.99 | N31: =M31/M30-1 -> 0.10651936

Sheet Scheme Recommendation
C5: Fundamentals | E5: Returns | H5: Risk/Rating | K5: Preference | M5: Weightage
C6: Scheme Name | D6: AuM (Cr) | E6: 3Y | F6: 5Y | G6: 10Y | H6: Beta | I6: Sharpe Ratio | J6: MC star Rating
B7: Large Cap | C7: Nippon India Large Cap Fund - Growth | D7: 39677.38 | E7: 0.2311 | F7: 0.2792 | G7: 0.1392 | H7: 0.98 | I7: 0.99 | J7: 5 | K7: =_xlfn.RANK.EQ(M7,$M$7:$M$9) -> 2 | M7: =D7*E7*F7*G7 -> 356.36708
C8: ICICI Prudential Bluechip Fund - Growth | D8: 68033.75 | E8: 0.2063 | F8: 0.2482 | G8: 0.1399 | H8: 0.88 | I8: 0.95 | J8: 5 | K8: =_xlfn.RANK.EQ(M8,$M$7:$M$9) -> 1 | M8: =D8*E8*F8*G8 -> 487.35242 | O8: 1st Preference
C9: HDFC Large Cap Fund - Growth | D9: 37315.11 | E9: 0.1913 | F9: 0.2435 | G9: 0.1264 | H9: 0.94 | I9: 0.83 | J9: 4 | K9: =_xlfn.RANK.EQ(M9,$M$7:$M$9) -> 3 | M9: =D9*E9*F9*G9 -> 219.70793 | O9: 2nd Preference
O10: 3rd Preference
B11: Mid Cap | C11: Motilal Oswal Midcap Fund - Growth | D11: 27780.18 | E11: 0.3287 | F11: 0.3805 | G11: 0.1735 | H11: 0.83 | I11: 1.17 | J11: 5 | K11: =_xlfn.RANK.EQ(M11,$M$11:$M$13) -> 3 | M11: =D11*E11*F11*G11 -> 602.82173
C12: Nippon India Growth Fund - Growth | D12: 34690.03 | E12: 0.2918 | F12: 0.3468 | G12: 0.1743 | H12: 0.94 | I12: 1.03 | J12: 4 | K12: =_xlfn.RANK.EQ(M12,$M$11:$M$13) -> 2 | M12: =D12*E12*F12*G12 -> 611.88025
C13: HDFC Mid-Cap Opportunities Fund - Growth | D13: 74909.76 | E13: 0.3031 | F13: 0.3436 | G13: 0.175 | H13: 0.87 | I13: 1.14 | J13: 4 | K13: =_xlfn.RANK.EQ(M13,$M$11:$M$13) -> 1 | M13: =D13*E13*F13*G13 -> 1365.2606
B15: Small Cap | C15: Bandhan Small Cap Fund - Regular Plan - Growth | D15: 10244.1 | E15: 0.3255 | F15: 0.3735 | G15: - | H15: 0.89 | I15: 1.1 | J15: 5 | K15: =_xlfn.RANK.EQ(M15,$M$15:$M$17) -> 2 | M15: =D15*E15*F15 -> 1245.4188
C16: Axis Small Cap Fund - Growth | D16: 23317.93 | E16: 0.2241 | F16: 0.318 | G16: 0.1832 | H16: 0.68 | I16: 0.78 | J16: 4 | K16: =_xlfn.RANK.EQ(M16,$M$15:$M$17) -> 3 | M16: =D16*E16*F16*G16 -> 304.42789
C17: Nippon India Small Cap Fund - Growth | D17: 58028.59 | E17: 0.2843 | F17: 0.4013 | G17: 0.2122 | H17: 0.84 | I17: 0.9 | J17: 4 | K17: =_xlfn.RANK.EQ(M17,$M$15:$M$17) -> 1 | M17: =D17*E17*F17*G17 -> 1404.8612
B19: ELSS | C19: SBI Long Term Equity Fund - Regular Plan - Growth | D19: 28506.07 | E19: 0.2799 | F19: 0.2967 | G19: 0.1418 | H19: 0.9 | I19: 1.28 | J19: 5 | K19: =_xlfn.RANK.EQ(M19,$M$19:$M$21) -> 1 | M19: =D19*E19*F19*G19 -> 335.68661
C20: DSP ELSS Tax Saver Fund - Regular Plan - Growth | D20: 16637.95 | E20: 0.2265 | F20: 0.2729 | G20: 0.158 | H20: 0.95 | I20: 0.93 | J20: 4 | K20: =_xlfn.RANK.EQ(M20,$M$19:$M$21) -> 2 | M20: =D20*E20*F20*G20 -> 162.49075
C21: HDFC ELSS Tax saver - Growth | D21: 16232.4 | E21: 0.2483 | F21: 0.2845 | G21: 0.1338 | H21: 0.81 | I21: 1.28 | J21: 5 | K21: =_xlfn.RANK.EQ(M21,$M$19:$M$21) -> 3 | M21: =D21*E21*F21*G21 -> 153.4256
